<?xml version='1.0'?>
<sdf version='1.4'>
<model name="thymio_predator">
    <link name='body'>
        <pose>0.0 0 0.030 1.570796 0 1.570796</pose>        
        <true>false</true>
        <inertial>
          <inertia>
            <ixx>0.00024333333</ixx>
            <ixy>0</ixy>
            <ixz>0</ixz>
            <iyy>0.00024333333</iyy>
            <iyz>0</iyz>
            <izz>0.00041073333</izz>
          </inertia>
          <mass>0.2</mass>
        </inertial>
        <collision name='collision_body'>
            <geometry>
                <mesh><uri>file:///home/jaqq/.gazebo/models/thymio_predator/thymio.obj</uri></mesh>
            </geometry>
        </collision>
        <visual name='visual_body'>
            <geometry>
                <mesh><uri>file:///home/jaqq/.gazebo/models/thymio_predator/thymio.obj</uri></mesh>
            </geometry>
            
            <material>
            <ambient>1 0 0 1</ambient>
            <diffuse>1 0 0 1</diffuse>
            <specular>0.1 1.0 0.1 1</specular>
            <emissive>0 0 0 0</emissive>
            </material> 
            
        </visual>
          
        <collision name='collision_ball'>
            <pose>0.0 -0.02 0.05 0 0 0</pose>
            <geometry>
                <sphere>
                    <radius>.01</radius>
                </sphere>
            </geometry>
            <surface>
                <friction>
                    <ode>
                        <mu>0</mu>
                        <mu2>0</mu2>
                        <slip1>1.0</slip1>
                        <slip2>1.0</slip2>
                    </ode>
                </friction>
            </surface>
        </collision>
        <visual name='visual_ball'>
           <pose>0.0 -0.02 0.05 0 0 0</pose>
            <geometry>
                <sphere>
                    <radius>.01</radius>
                </sphere>
            </geometry>
        </visual>   
         
    </link>
    
    <link name="left_wheel">
    <pose>-0.003 0.036 0.025 0 1.5707 1.5707</pose>
    <inertial>
      <inertia>
        <ixx>0.00000546875</ixx>
        <ixy>0</ixy>
        <ixz>0</ixz>
        <iyy>0.00000546875</iyy>
        <iyz>0</iyz>
        <izz>0.0000109375</izz>
      </inertia>
      <mass>0.035</mass>
    </inertial>
    <collision name="collision">
        <geometry>
            <cylinder>
                <radius>.025</radius>
                <length>.05</length>
            </cylinder>
        </geometry>
    </collision>
    <visual name="visual">
        <geometry>
            <cylinder>
                <radius>.025</radius>
                <length>.05</length>
            </cylinder>
        </geometry>
    </visual>
    </link>
    
    <joint type="revolute" name="left_wheel_hinge">
        <pose>0 0 0 0 0 0</pose>
        <child>left_wheel</child>
        <parent>body</parent>
        <axis>
            <xyz>0 1 0</xyz>
        </axis>
    </joint>
    
    <link name="right_wheel">
    <pose>-0.003 -0.036 0.025 0 1.5707 1.5707</pose>
    <inertial>
      <inertia>
        <ixx>0.00000546875</ixx>
        <ixy>0</ixy>
        <ixz>0</ixz>
        <iyy>0.00000546875</iyy>
        <iyz>0</iyz>
        <izz>0.0000109375</izz>
      </inertia>
      <mass>0.035</mass>
    </inertial>
    <collision name="collision">
        <geometry>
            <cylinder>
                <radius>.025</radius>
                <length>.05</length>
            </cylinder>
        </geometry>
    </collision>
    <visual name="visual">
        <geometry>
            <cylinder>
                <radius>.025</radius>
                <length>.05</length>
            </cylinder>
        </geometry>
    </visual>
    </link>
    
    <joint type="revolute" name="right_wheel_hinge">
        <pose>0 0 0 0 0 0</pose>
        <child>right_wheel</child>
        <parent>body</parent>
        <axis>
            <xyz>0 1 0</xyz>
        </axis>
    </joint>
    
</model>
</sdf>
